<?xml version="1.0" ?>
<robot name="cobot">

<material name="silver">
  <color rgba="0.7 0.7 0.7 1.0"/>
</material>

<link name="base_link">
  <inertial>
    <origin
      xyz="0.0010569805350138673 0.0007297344522584362 0.01829217339489528"
      rpy="0 0 0" />
    <mass
      value="0.9757252027596308" />
    <inertia
      ixx="0.001614"
      iyy="0.0017"
      izz="0.002741"
      ixy="-1.4e-05"
      iyz="-7e-06"
      ixz="-0.0" />
  </inertial>

  <visual>
    <origin
      xyz="0 0 0"
      rpy="0 0 0" />
    <geometry>
      <mesh
        filename="package://cobot_description/meshes/base_link.stl"
        scale="0.001 0.001 0.001" />
    </geometry>
    <material
      name="silver" />
  </visual>

  <collision>
    <origin
      xyz="0 0 0"
      rpy="0 0 0" />
    <geometry>
      <mesh
        filename="package://cobot_description/meshes/base_link.stl"
        scale="0.001 0.001 0.001" />
    </geometry>
  </collision>
</link>

<link name="link1">
  <inertial>
    <origin
      xyz="-0.003818008823720768 0.008441513827613 0.03204494242786362"
      rpy="0 0 0" />
    <mass
      value="0.8487763548317978" />
    <inertia
      ixx="0.000968"
      iyy="0.001205"
      izz="0.000724"
      ixy="3.4e-05"
      iyz="-0.000103"
      ixz="-7.7e-05" />
  </inertial>
  
  <visual>
    <origin
      xyz="-0.0 -0.0 -0.05675"
      rpy="0 0 0" />
    <geometry>
      <mesh
        filename="package://cobot_description/meshes/link1.stl"
        scale="0.001 0.001 0.001" />
    </geometry>
    <material
      name="silver" />
  </visual>

  <collision>
    <origin
      xyz="-0.0 -0.0 -0.05675"
      rpy="0 0 0" />
    <geometry>
      <mesh
        filename="package://cobot_description/meshes/link1.stl"
        scale="0.001 0.001 0.001" />
    </geometry>
  </collision>
</link>

<link name="link2">
  <inertial>
    <origin
      xyz="0.002214238815772403 -0.011894670876730499 0.06020229512696279"
      rpy="0 0 0" />
    <mass
      value="0.6612420873424198" />
    <inertia
      ixx="0.001921"
      iyy="0.001969"
      izz="0.000127"
      ixy="-2e-06"
      iyz="-2e-06"
      ixz="-1e-06" />
  </inertial>

  <visual>
    <origin
      xyz="-0.01392 7e-06 -0.127026"
      rpy="0 0 0" />
    <geometry>
      <mesh
        filename="package://cobot_description/meshes/link2.stl"
        scale="0.001 0.001 0.001" />
    </geometry>
    <material
      name="silver" />
  </visual>

  <collision>
    <origin
      xyz="-0.01392 7e-06 -0.127026"
      rpy="0 0 0" />
    <geometry>
      <mesh
        filename="package://cobot_description/meshes/link2.stl"
        scale="0.001 0.001 0.001" />
    </geometry>
  </collision>
</link>

<link name="link3">
  <inertial>
    <origin
      xyz="-0.0006937756215695916 0.008652145666434768 0.0409322245782118"
      rpy="0 0 0" />
    <mass
      value="0.4123818105357045" />
    <inertia
      ixx="0.000447"
      iyy="0.000468"
      izz="8.7e-05"
      ixy="2e-06"
      iyz="5e-06"
      ixz="-7e-06" />
  </inertial>

  <visual>
    <origin
      xyz="-0.013905 7e-06 -0.247026"
      rpy="0 0 0" />
    <geometry>
      <mesh
        filename="package://cobot_description/meshes/link3.stl"
        scale="0.001 0.001 0.001" />
    </geometry>
    <material name="silver" />
  </visual>

  <collision>
    <origin
      xyz="-0.013905 7e-06 -0.247026"
      rpy="0 0 0" />
    <geometry>
      <mesh
        filename="package://cobot_description/meshes/link3.stl"
        scale="0.001 0.001 0.001" />
    </geometry>
  </collision>
</link>

<link name="link4">
  <inertial>
    <origin
      xyz="-0.0002076619932401616 0.005563955264345595 0.02139744743586941"
      rpy="0 0 0" />
    <mass
      value="0.1688382109185934" />
    <inertia
      ixx="4.4e-05"
      iyy="5.8e-05"
      izz="3.2e-05"
      ixy="-0.0"
      iyz="-4e-06"
      ixz="0.0" />
  </inertial>

  <visual>
    <origin
      xyz="-0.013495 -0.010537 -0.336776"
      rpy="0 0 0" />
    <geometry>
      <mesh
        filename="package://cobot_description/meshes/link4.stl"
        scale="0.001 0.001 0.001" />
    </geometry>
    <material
      name="silver" />
  </visual>

  <collision>
    <origin
      xyz="-0.013495 -0.010537 -0.336776"
      rpy="0 0 0" />
    <geometry>
      <mesh
        filename="package://cobot_description/meshes/link4.stl"
        scale="0.001 0.001 0.001" />
    </geometry>
  </collision>
</link>

<link name="link5">
  <inertial>
    <origin
      xyz="0.0009180511930666074 -0.0026770648599710144 0.023252917458090605"
      rpy="0 0 0" />
    <mass
      value="0.17229950863980814" />
    <inertia
      ixx="9.6e-05"
      iyy="8.8e-05"
      izz="2.6e-05"
      ixy="0.0"
      iyz="1.8e-05"
      ixz="-3e-06" />
  </inertial>

  <visual>
    <origin
      xyz="-0.013547 -0.024737 -0.369276"
      rpy="0 0 0" />
    <geometry>
      <mesh
        filename="package://cobot_description/meshes/link5.stl"
        scale="0.001 0.001 0.001" />
    </geometry>
    <material
      name="silver"/>
  </visual>

  <collision>
    <origin
      xyz="-0.013547 -0.024737 -0.369276"
      rpy="0 0 0" />
    <geometry>
      <mesh
        filename="package://cobot_description/meshes/link5.stl"
        scale="0.001 0.001 0.001" />
    </geometry>
  </collision>
</link>

<link name="in_right_grip">
  <inertial>
    <origin
      xyz="-0.0006351808581316672 0.00432633092858755 0.014644586508523127"
      rpy="0 0 0" />
    <mass
      value="0.020498186106830463" />
    <inertia
      ixx="3e-06"
      iyy="3e-06"
      izz="1e-06"
      ixy="0.0"
      iyz="-1e-06"
      ixz="-0.0"/>
  </inertial>

  <visual>
    <origin
      xyz="-0.015633 -0.02405 -0.42841"
      rpy="0 0 0" />
    <geometry>
      <mesh
        filename="package://cobot_description/meshes/in_right_grip.stl"
        scale="0.001 0.001 0.001" />
    </geometry>
    <material
      name="silver" />
  </visual>

  <collision>
    <origin
      xyz="-0.015633 -0.02405 -0.42841"
      rpy="0 0 0" />
    <geometry>
      <mesh
        filename="package://cobot_description/meshes/in_right_grip.stl"
        scale="0.001 0.001 0.001" />
    </geometry>
  </collision>
</link>

<link name="in_left_grip">
  <inertial>
    <origin
      xyz="-0.0007181665729370061 -0.004855388988816466 0.014473452058062775"
      rpy="0 0 0" />
    <mass
      value="0.020498186106830463" />
    <inertia
      ixx="3e-06"
      iyy="3e-06"
      izz="1e-06"
      ixy="0.0"
      iyz="1e-06"
      ixz="0.0" />
  </inertial>

  <visual>
    <origin
      xyz="-0.015511 -0.01074 -0.428335"
      rpy="0 0 0" />
    <geometry>
      <mesh
        filename="package://cobot_description/meshes/in_left_grip.stl"
        scale="0.001 0.001 0.001" />
    </geometry>
    <material
      name="silver" />
  </visual>

  <collision>
    <origin
      xyz="-0.015511 -0.01074 -0.428335"
      rpy="0 0 0" />
    <geometry>
      <mesh
        filename="package://cobot_description/meshes/in_left_grip.stl"
        scale="0.001 0.001 0.001" />
    </geometry>
  </collision>
</link>

<link name="out_right_grip">
  <inertial>
    <origin
      xyz="0.001718746609355823 0.0060517958020296775 0.009753075365702468"
      rpy="0 0 0" />
    <mass 
      value="0.03206774948119643" />
    <inertia
      ixx="7e-06"
      iyy="5e-06"
      izz="2e-06"
      ixy="0.0"
      iyz="-2e-06"
      ixz="1e-06" />
  </inertial>

  <visual>
    <origin
      xyz="-0.016434 -0.027552 -0.407598"
      rpy="0 0 0" />
    <geometry>
      <mesh
        filename="package://cobot_description/meshes/out_right_grip.stl"
        scale="0.001 0.001 0.001" />
    </geometry>
    <material
      name="silver" />
  </visual>

  <collision>
    <origin
      xyz="-0.016434 -0.027552 -0.407598"
      rpy="0 0 0" />
    <geometry>
      <mesh
        filename="package://cobot_description/meshes/out_right_grip.stl"
        scale="0.001 0.001 0.001" />
    </geometry>
  </collision>
</link>

<link name="out_left_grip">
  <inertial>
    <origin
      xyz="0.0016870125804937762 -0.006851070724163324 0.011071981124217367"
      rpy="0 0 0" />
    <mass
      value="0.02733538421745774" />
    <inertia
      ixx="6e-06"
      iyy="5e-06"
      izz="2e-06"
      ixy="-0.0"
      iyz="2e-06"
      ixz="1e-06" />
  </inertial>

  <visual>
    <origin
      xyz="-0.016251 -0.00746 -0.407484"
      rpy="0 0 0" />
    <geometry>
      <mesh
        filename="package://cobot_description/meshes/out_left_grip.stl"
        scale="0.001 0.001 0.001" />
    </geometry>
    <material
      name="silver" />
  </visual>

  <collision>
    <origin
      xyz="-0.016251 -0.00746 -0.407484"
      rpy="0 0 0" />
    <geometry>
      <mesh
        filename="package://cobot_description/meshes/out_left_grip.stl"
        scale="0.001 0.001 0.001" />
    </geometry>
  </collision>
</link>

<link name="left_gripper">
  <inertial>
    <origin
      xyz="-0.0007973268186895303 0.006294598773784492 0.029093411847490813"
      rpy="0 0 0" />
    <mass
      value="0.0574367398539114" />
    <inertia
      ixx="2e-05"
      iyy="1.9e-05"
      izz="3e-06"
      ixy="0.0"
      iyz="-4e-06"
      ixz="0.0" />
  </inertial>

  <visual>
    <origin
      xyz="-0.015316 0.007935 -0.438489"
      rpy="0 0 0" />
    <geometry>
      <mesh
        filename="package://cobot_description/meshes/left_gripper.stl"
        scale="0.001 0.001 0.001" />
    </geometry>
    <material
      name="silver" />
  </visual>

  <collision>
    <origin
      xyz="-0.015316 0.007935 -0.438489"
      rpy="0 0 0" />
    <geometry>
      <mesh
        filename="package://cobot_description/meshes/left_gripper.stl"
        scale="0.001 0.001 0.001" />
    </geometry>
  </collision>
</link>

<link name="right_gripper">
  <inertial>
    <origin
      xyz="-0.0006522798682768623 -0.006645060979379405 0.02916261432592454"
      rpy="0 0 0" />
    <mass
      value="0.05715084388035935" />
    <inertia
      ixx="1.9e-05"
      iyy="1.9e-05"
      izz="3e-06"
      ixy="-0.0"
      iyz="4e-06"
      ixz="0.0" />
  </inertial>

  <visual>
    <origin
      xyz="-0.015503 -0.042612 -0.438775"
      rpy="0 0 0" />
    <geometry>
      <mesh
        filename="package://cobot_description/meshes/right_gripper.stl"
        scale="0.001 0.001 0.001" />
    </geometry>
    <material
      name="silver" />
  </visual>

  <collision>
    <origin
      xyz="-0.015503 -0.042612 -0.438775"
      rpy="0 0 0" />
    <geometry>
      <mesh
        filename="package://cobot_description/meshes/right_gripper.stl"
        scale="0.001 0.001 0.001" />
    </geometry>
  </collision>
</link>

<joint name="joint_base_link_to_link1" type="continuous">
  <origin xyz="0.0 0.0 0.05675" rpy="0 0 0"/>
  <parent link="base_link"/>
  <child link="link1"/>
  <axis xyz="-0.0 -0.0 1.0"/>
</joint>

<joint name="joint_link1_to_link2" type="continuous">
  <origin xyz="0.01392 -7e-06 0.070276" rpy="0 0 0"/>
  <parent link="link1"/>
  <child link="link2"/>
  <axis xyz="-0.000506 -1.0 -0.0"/>
</joint>

<joint name="joint_link2_to_link3" type="continuous">
  <origin xyz="-1.5e-05 0.0 0.12" rpy="0 0 0"/>
  <parent link="link2"/>
  <child link="link3"/>
  <axis xyz="0.000506 1.0 0.0"/>
</joint>

<joint name="joint_link3_to_link4" type="continuous">
  <origin xyz="-0.00041 0.010544 0.08975" rpy="0 0 0"/>
  <parent link="link3"/>
  <child link="link4"/>
  <axis xyz="-0.0024 1e-06 0.999997"/>
</joint>

<joint name="joint_link4_to_link5" type="continuous">
  <origin xyz="5.2e-05 0.0142 0.0325" rpy="0 0 0"/>
  <parent link="link4"/>
  <child link="link5"/>
  <axis xyz="0.009166 0.999958 2.1e-05"/>
</joint>

<joint name="joint_link5_to_in_right_grip" type="continuous">
  <origin xyz="0.002086 -0.000687 0.059134" rpy="0 0 0"/>
  <parent link="link5"/>
  <child link="in_right_grip"/>
  <axis xyz="-0.999947 0.009166 -0.004789"/>
</joint>

<joint name="joint_link5_to_in_left_grip" type="continuous">
  <origin xyz="0.001964 -0.013997 0.059059" rpy="0 0 0"/>
  <parent link="link5"/>
  <child link="in_left_grip"/>
  <axis xyz="-0.999947 0.009166 -0.004789"/>
</joint>

<joint name="joint_link5_to_out_right_grip" type="continuous">
  <origin xyz="0.002887 0.002815 0.038322" rpy="0 0 0"/>
  <parent link="link5"/>
  <child link="out_right_grip"/>
  <axis xyz="0.999947 -0.009166 0.004789"/>
</joint>

<joint name="joint_link5_to_out_left_grip" type="continuous">
  <origin xyz="0.002704 -0.017277 0.038208" rpy="0 0 0"/>
  <parent link="link5"/>
  <child link="out_left_grip"/>
  <axis xyz="0.999947 -0.009166 0.004789"/>
</joint>

<joint name="joint_out_left_grip_to_left_gripper" type="continuous">
  <origin xyz="-0.000935 -0.015395 0.031005" rpy="0 0 0"/>
  <parent link="out_left_grip"/>
  <child link="left_gripper"/>
  <axis xyz="-0.999947 0.009166 -0.004789"/>
</joint>

<joint name="joint_out_right_grip_to_right_gripper" type="continuous">
  <origin xyz="-0.000931 0.01506 0.031177" rpy="0 0 0"/>
  <parent link="out_right_grip"/>
  <child link="right_gripper"/>
  <axis xyz="-0.999947 0.009166 -0.004789"/>
</joint>

</robot>
