<?xml version="1.0" encoding="utf-8"?>
<robot xmlns:xacro="https://www.ros.org/wiki/xacro">

  <xacro:macro name="cobot_description">

    <material name="silver">
      <color rgba="0.7 0.7 0.7 1.0"/>
    </material>
    
    <!-- base_link -->
    <link name="base_link">
      <inertial>
        <origin
          xyz="0.0010569805350138673 0.0007297344522584362 0.01829217339489528"
          rpy="0 0 0" />
        <mass
          value="0.9757252027596308" />
        <inertia
          ixx="0.001614"
          iyy="0.0017"
          izz="0.002741"
          ixy="-1.4e-05"
          iyz="-7e-06"
          ixz="-0.0" />
      </inertial>
    
      <visual>
        <origin
          xyz="0 0 0"
          rpy="0 0 0" />
        <geometry>
          <mesh
            filename="package://cobot_description/meshes/base_link.stl"
            scale="0.001 0.001 0.001" />
        </geometry>
        <material
          name="silver" />
      </visual>
    
      <collision>
        <origin
          xyz="0 0 0"
          rpy="0 0 0" />
        <geometry>
          <mesh
            filename="package://cobot_description/meshes/base_link.stl"
            scale="0.001 0.001 0.001" />
        </geometry>
      </collision>
    </link>
    
    <!-- link1 -->
    <link name="link1">
      <inertial>
        <origin
          xyz="-0.003818008823720768 0.008441513827613 0.03204494242786362"
          rpy="0 0 0" />
        <mass
          value="0.8487763548317978" />
        <inertia
          ixx="0.000968"
          iyy="0.001205"
          izz="0.000724"
          ixy="3.4e-05"
          iyz="-0.000103"
          ixz="-7.7e-05" />
      </inertial>
      
      <visual>
        <origin
          xyz="0 0 0"
          rpy="0 0 0" />
        <geometry>
          <mesh
            filename="package://cobot_description/meshes/link1.stl"
            scale="0.001 0.001 0.001" />
        </geometry>
        <material
          name="silver" />
      </visual>
    
      <collision>
        <origin
          xyz="0 0 0"
          rpy="0 0 0" />
        <geometry>
          <mesh
            filename="package://cobot_description/meshes/link1.stl"
            scale="0.001 0.001 0.001" />
        </geometry>
      </collision>
    </link>
    
    <!-- link2 -->
    <link name="link2">
      <inertial>
        <origin
          xyz="0.06020229512696279 -0.002214238815772403 0.011894670876730499"
          rpy="0 0 0" />
        <mass
          value="0.6612420873424198" />
        <inertia
          ixx="0.000127"
          iyy="0.001921"
          izz="0.001969"
          ixy="-2e-06"
          iyz="2e-06"
          ixz="1e-06" />
      </inertial>
    
      <visual>
        <origin
          xyz="0 0 0"
          rpy="0 0 0" />
        <geometry>
          <mesh
            filename="package://cobot_description/meshes/link2.stl"
            scale="0.001 0.001 0.001" />
        </geometry>
        <material
          name="silver" />
      </visual>
    
      <collision>
        <origin
          xyz="0 0 0"
          rpy="0 0 0" />
        <geometry>
          <mesh
            filename="package://cobot_description/meshes/link2.stl"
            scale="0.001 0.001 0.001" />
        </geometry>
      </collision>
    </link>
    
    <!-- link3 -->
    <link name="link3">
      <inertial>
        <origin
          xyz="0.0409322245782118 -0.0006937756215695916 -0.008652145666434768"
          rpy="0 0 0" />
        <mass
          value="0.4123818105357045" />
        <inertia
          ixx="8.7e-05"
          iyy="0.000447"
          izz="0.000468"
          ixy="-7e-06"
          iyz="-2e-06"
          ixz="-5e-06" />
      </inertial>
    
      <visual>
        <origin
          xyz="0 0 0"
          rpy="0 0 0" />
        <geometry>
          <mesh
            filename="package://cobot_description/meshes/link3.stl"
            scale="0.001 0.001 0.001" />
        </geometry>
        <material name="silver" />
      </visual>
    
      <collision>
        <origin
          xyz="0 0 0"
          rpy="0 0 0" />
        <geometry>
          <mesh
            filename="package://cobot_description/meshes/link3.stl"
            scale="0.001 0.001 0.001" />
        </geometry>
      </collision>
    </link>
    
    <!-- link4 -->
    <link name="link4">
      <inertial>
        <origin
          xyz="0.0002076619932401616 -0.005563955264345595 0.02139744743586941"
          rpy="0 0 0" />
        <mass
          value="0.1688382109185934" />
        <inertia
          ixx="4.4e-05"
          iyy="5.8e-05"
          izz="3.2e-05"
          ixy="0.0"
          iyz="4e-06"
          ixz="-0.0" />
      </inertial>
    
      <visual>
        <origin
          xyz="0 0 0"
          rpy="0 0 0" />
        <geometry>
          <mesh
            filename="package://cobot_description/meshes/link4.stl"
            scale="0.001 0.001 0.001" />
        </geometry>
        <material
          name="silver" />
      </visual>
    
      <collision>
        <origin
          xyz="0 0 0"
          rpy="0 0 0" />
        <geometry>
          <mesh
            filename="package://cobot_description/meshes/link4.stl"
            scale="0.001 0.001 0.001" />
        </geometry>
      </collision>
    </link>

    <link name="link5">
      <inertial>
        <origin
          xyz="0.023252917458090605 0.0009180511930666074 -0.0026770648599710144"
          rpy="1.5708 0 1.5708" />
        <mass
          value="0.17229950863980814" />
        <inertia
          ixx="9.6e-05"
          iyy="8.8e-05"
          izz="2.6e-05"
          ixy="0.0"
          iyz="1.8e-05"
          ixz="-3e-06" />
      </inertial>
    
      <visual>
        <origin
          xyz="0 0 0"
          rpy="0 0 0" />
        <geometry>
          <mesh
            filename="package://cobot_description/meshes/link5.stl"
            scale="0.001 0.001 0.001" />
        </geometry>
        <material
          name="silver"/>
      </visual>
    
      <collision>
        <origin
          xyz="0 0 0"
          rpy="0 0 0" />
        <geometry>
          <mesh
            filename="package://cobot_description/meshes/link5.stl"
            scale="0.001 0.001 0.001" />
        </geometry>
      </collision>
    </link>

    <link name="in_right_grip">
      <visual>
        <origin
          xyz="0 0 0"
          rpy="0 0 0" />
        <geometry>
          <mesh
            filename="package://cobot_description/meshes/in_right_grip.stl"
            scale="0.001 0.001 0.001" />
        </geometry>
        <material
          name="silver" />
      </visual>
    
      <collision>
        <origin
          xyz="0 0 0"
          rpy="0 0 0" />
        <geometry>
          <mesh
            filename="package://cobot_description/meshes/in_right_grip.stl"
            scale="0.001 0.001 0.001" />
        </geometry>
      </collision>
    </link>
    
    <link name="in_left_grip">
      <visual>
        <origin
          xyz="0 0 0"
          rpy="0 0 0" />
        <geometry>
          <mesh
            filename="package://cobot_description/meshes/in_left_grip.stl"
            scale="0.001 0.001 0.001" />
        </geometry>
        <material
          name="silver" />
      </visual>
    
      <collision>
        <origin
          xyz="0 0 0"
          rpy="0 0 0" />
        <geometry>
          <mesh
            filename="package://cobot_description/meshes/in_left_grip.stl"
            scale="0.001 0.001 0.001" />
        </geometry>
      </collision>
    </link>
    
    <link name="out_right_grip">
      <visual>
        <origin
          xyz="0 0 0"
          rpy="0 0 0" />
        <geometry>
          <mesh
            filename="package://cobot_description/meshes/out_right_grip.stl"
            scale="0.001 0.001 0.001" />
        </geometry>
        <material
          name="silver" />
      </visual>
    
      <collision>
        <origin
          xyz="0 0 0"
          rpy="0 0 0" />
        <geometry>
          <mesh
            filename="package://cobot_description/meshes/out_right_grip.stl"
            scale="0.001 0.001 0.001" />
        </geometry>
      </collision>
    </link>
    
    <link name="out_left_grip">
      <visual>
        <origin
          xyz="0 0 0"
          rpy="0 0 0" />
        <geometry>
          <mesh
            filename="package://cobot_description/meshes/out_left_grip.stl"
            scale="0.001 0.001 0.001" />
        </geometry>
        <material
          name="silver" />
      </visual>
    
      <collision>
        <origin
          xyz="0 0 0"
          rpy="0 0 0" />
        <geometry>
          <mesh
            filename="package://cobot_description/meshes/out_left_grip.stl"
            scale="0.001 0.001 0.001" />
        </geometry>
      </collision>
    </link>

    <link name="right_gripper">
      <visual>
        <origin
          xyz="0 0 0"
          rpy="0 0 -0.2618" />
        <geometry>
          <mesh
            filename="package://cobot_description/meshes/right_gripper.stl"
            scale="0.001 0.001 0.001" />
        </geometry>
        <material
          name="silver" />
      </visual>
    
      <collision>
        <origin
          xyz="0 0 0"
          rpy="0 0 0" />
        <geometry>
          <mesh
            filename="package://cobot_description/meshes/right_gripper.stl"
            scale="0.001 0.001 0.001" />
        </geometry>
      </collision>
    </link>
    
    <link name="left_gripper">
      <visual>
        <origin
          xyz="0 0 0"
          rpy="0 0 0.2618" />
        <geometry>
          <mesh
            filename="package://cobot_description/meshes/left_gripper.stl"
            scale="0.001 0.001 0.001" />
        </geometry>
        <material
          name="silver" />
      </visual>
    
      <collision>
        <origin
          xyz="0 0 0"
          rpy="0 0 0" />
        <geometry>
          <mesh
            filename="package://cobot_description/meshes/left_gripper.stl"
            scale="0.001 0.001 0.001" />
        </geometry>
      </collision>
    </link>

    <!-- joint -->
    
    <joint name="joint_base_link_to_link1" type="revolute">
      <origin
        xyz="0 0 0.05675"
        rpy="0 0 0" />
      <parent
        link="base_link" />
      <child
        link="link1" />
      <axis
        xyz="0 0 1" />
      <limit
        effort="1000.0" lower="-1.5708" upper="1.5708" velocity="0.5" />
    </joint>
    
    <joint name="joint_link1_to_link2" type="revolute">
      <origin
        xyz="0.01392 0 0.070276"
        rpy="1.5708 -1.5708 0" />
      <parent
        link="link1" />
      <child
        link="link2" />
      <axis
        xyz="0 0 1" />
      <limit
        effort="1000.0" lower="-1.5708" upper="1.5708" velocity="0.5" />
    </joint>
    
    <joint name="joint_link2_to_link3" type="revolute">
      <origin
        xyz="0.12 0 0"
        rpy="0 0 0"/>
      <parent
        link="link2"/>
      <child
        link="link3"/>
      <axis
        xyz="0 0 -1"/>
      <limit
        effort="1000.0" lower="-1.5708" upper="1.5708" velocity="0.5" />
    </joint>
    
    <joint name="joint_link3_to_link4" type="revolute">
      <origin
        xyz="0.08975 0 -0.010544"
        rpy="-1.5708 0 -1.5708" />
      <parent
        link="link3" />
      <child
        link="link4" />
      <axis
        xyz="0 0 1" />
      <limit
        effort="1000.0" lower="-1.5708" upper="1.5708" velocity="0.5" />
    </joint>
    
    <joint name="joint_link4_to_link5" type="revolute">
      <origin
        xyz="0 -0.0142 0.0325"
        rpy="1.5708 -1.5708 0" />
      <parent
        link="link4" />
      <child
        link="link5" />
      <axis
        xyz="0 0 1" />
      <limit
        effort="1000.0" lower="-1.5708" upper="1.5708" velocity="0.5" />
    </joint>
    
    <!-- joint_link5_to_out_left_grip -->
    <joint name="gripper" type="revolute">
      <origin
        xyz="0.038208 0.00536837 -0.017277"
        rpy="-1.5708 0.2618 0"/>
      <parent
        link="link5"/>
      <child
        link="out_left_grip"/>
      <axis
         xyz="0 0 -1"/>
      <limit
        effort="1000.0" lower="-0.500" upper="0.250" velocity="0.5" />
    </joint>

    <joint name="joint_link5_to_out_right_grip" type="revolute">
      <origin
        xyz="0.038322 0.00536837 0.002815"
        rpy="-1.5708 -0.2618 0"/>
      <parent
        link="link5"/>
      <child
        link="out_right_grip"/>
      <axis
        xyz="0 0 1"/>
      <mimic
        joint="gripper" multiplier="1.0" offset="0" />
      <limit
        effort="1000.0" lower="-1.5708" upper="1.5708" velocity="0.5" />
    </joint>
    
    <joint name="joint_link5_to_in_left_grip" type="revolute">
      <origin
        xyz="0.059059 -0.002086 -0.013997"
        rpy="-1.5708 0.34906 0" />
      <parent
        link="link5"/>
      <child
        link="in_left_grip"/>
      <axis
        xyz="0 0 -1"/>
      <mimic
        joint="gripper" multiplier="1.2" offset="0" />
      <limit
        effort="1000.0" lower="-1.5708" upper="1.5708" velocity="0.5" />
    </joint>
    
    <joint name="joint_link5_to_in_right_grip" type="revolute">
      <origin
        xyz="0.059134 -0.002086 -0.000687"
        rpy="-1.5708 -0.34906 0" />
      <parent
        link="link5" />
      <child
        link="in_right_grip" />
      <axis
        xyz="0 0 1" />
      <mimic
        joint="gripper" multiplier="1.2" offset="0" />
      <limit
        effort="1000.0" lower="-1.5708" upper="1.5708" velocity="0.5" />
    </joint>
    
    <joint name="joint_out_left_grip_to_left_gripper" type="revolute">
      <origin
        xyz="0.0339442 0.00682491 -0.0042874"
        rpy="0 0 -0.5236" />
      <parent
        link="out_left_grip"/>
      <child
        link="left_gripper"/>
      <axis
        xyz="0 0 1"/>
      <mimic
        joint="gripper" multiplier="1.0" offset="0" />
      <limit
        effort="1000.0" lower="-1.5708" upper="1.5708" velocity="0.5" />
    </joint>

    <joint name="joint_out_right_grip_to_right_gripper" type="revolute">
      <origin
        xyz="0.0339442 -0.00682491 -0.0030837"
        rpy="0 0 0.5236"/>
      <parent
        link="out_right_grip"/>
      <child
        link="right_gripper"/>
      <axis
        xyz="0 0 -1"/>
      <mimic
        joint="gripper" multiplier="1.0" offset="0" />
      <limit
        effort="1000.0" lower="-1.5708" upper="1.5708" velocity="0.5" />
    </joint>

    <!-- end effector -->
    <link name="end_effector" />
    <joint name="end_effector" type="fixed">
      <origin
        xyz="0.105 0 -0.0075"
        rpy="0 0 0" />
      <parent
        link="link5" />
      <child
        link="end_effector" />
    </joint>

  </xacro:macro>
</robot>